Workbook

Sheet Torque Plan Summary · Scenario
A1: Torque Plan Summary · Scenario comparison: month 12 (Sep 2027)
A2: Financial model (4 pages) · Main Scenario
A4: Variable / dimension | B4: 2027-09 | C4: 2027-09 > Conservative | D4: 2027-09 > Optimistic
A5: Paying customers | B5: =SUM('Monthly Financial Plan · Torque'!M7,'Monthly Financial Plan · Torque'!M8,'Monthly Financial Plan · Torque'!M9) -> 135.7862 | C5: =SUM('Model inputs'!P85,'Model inputs'!P86,'Model inputs'!P87) -> 31.047134 | D5: =SUM('Model inputs'!P81,'Model inputs'!P82,'Model inputs'!P83) -> 375.68726
A6: Verified pull requests | B6: =SUM('Monthly Financial Plan · Torque'!M15,'Monthly Financial Plan · Torque'!M16,'Monthly Financial Plan · Torque'!M17)*'Torque Assumptions · Run cost a'!B17 -> 3964.3736 | C6: =SUM('Model inputs'!P34,'Model inputs'!P35,'Model inputs'!P36)*'Model inputs'!B125 -> 868.67197 | D6: =SUM('Model inputs'!P30,'Model inputs'!P31,'Model inputs'!P32)*'Model inputs'!B124 -> 10720.107
A7: Total revenue | B7: =SUM('Monthly Financial Plan · Torque'!M20,'Monthly Financial Plan · Torque'!M21,'Monthly Financial Plan · Torque'!M22)+SUM('Monthly Financial Plan · Torque'!M24,'Monthly Financial Plan · Torque'!M25,'Monthly Financial Plan · Torque'!M26) -> 16691.007 | C7: =SUM('Model inputs'!P109,'Model inputs'!P110,'Model inputs'!P111)+SUM('Model inputs'!P73,'Model inputs'!P74,'Model inputs'!P75) -> 3955.5457 | D7: =SUM('Model inputs'!P105,'Model inputs'!P106,'Model inputs'!P107)+SUM('Model inputs'!P69,'Model inputs'!P70,'Model inputs'!P71) -> 45459.549
A8: Cost of revenue | B8: ='Monthly Financial Plan · Torque'!M28+'Monthly Financial Plan · Torque'!M29+'Monthly Financial Plan · Torque'!M30+'Monthly Financial Plan · Torque'!M31+'Monthly Financial Plan · Torque'!M32+'Monthly Financial Plan · Torque'!M33 -> 7797.433 | C8: ='Model inputs'!P39+'Model inputs'!P93+'Model inputs'!P62+'Model inputs'!P99+'Model inputs'!P24+'Model inputs'!P90 -> 3009.3765 | D8: ='Model inputs'!P38+'Model inputs'!P92+'Model inputs'!P61+'Model inputs'!P98+'Model inputs'!P23+'Model inputs'!P89 -> 15195.568
A9: Gross margin before credits | B9: =IFERROR('Monthly Financial Plan · Torque'!M35/'Torque Plan Summary · Scenario'!B7,"") -> 0.53283628 | C9: =IFERROR('Model inputs'!P19/'Torque Plan Summary · Scenario'!C7,"") -> 0.23920068 | D9: =IFERROR('Model inputs'!P18/'Torque Plan Summary · Scenario'!D7,"") -> 0.66573429
A10: Operating expenses | B10: ='Monthly Financial Plan · Torque'!M41+'Monthly Financial Plan · Torque'!M42+'Monthly Financial Plan · Torque'!M43 -> 700 | C10: ='Model inputs'!P118+'Model inputs'!P96+'Model inputs'!P42 -> 700 | D10: ='Model inputs'!P117+'Model inputs'!P95+'Model inputs'!P41 -> 700
A11: Net cash flow before credits | B11: ='Monthly Financial Plan · Torque'!M35-'Torque Plan Summary · Scenario'!B10 -> 8193.5743 | C11: ='Model inputs'!P19-'Torque Plan Summary · Scenario'!C10 -> 246.16924 | D11: ='Model inputs'!P18-'Torque Plan Summary · Scenario'!D10 -> 29563.98
A12: AI spend limit at target margin | B12: ='Torque Plan Summary · Scenario'!B7*(1-'Torque Assumptions · Growth & o'!B12)-'Monthly Financial Plan · Torque'!M32-'Monthly Financial Plan · Torque'!M33-'Monthly Financial Plan · Torque'!M30-'Monthly Financial Plan · Torque'!M31 -> 5001.8953 | C12: ='Torque Plan Summary · Scenario'!C7*(1-'Model inputs'!B115)-'Model inputs'!P24-'Model inputs'!P90-'Model inputs'!P62-'Model inputs'!P99 -> 1062.1565 | D12: ='Torque Plan Summary · Scenario'!D7*(1-'Model inputs'!B114)-'Model inputs'!P23-'Model inputs'!P89-'Model inputs'!P61-'Model inputs'!P98 -> 13946.948

Sheet Monthly Financial Plan · Torque
A1: Monthly Financial Plan · Torque monthly financial plan
A2: Financial model (4 pages) · Main Scenario
A4: Variable / dimension | B4: 2026-10 | C4: 2026-11 | D4: 2026-12 | E4: 2027-01 | F4: 2027-02 | G4: 2027-03 | H4: 2027-04 | I4: 2027-05 | J4: 2027-06 | K4: 2027-07 | L4: 2027-08 | M4: 2027-09
A5: New customers | B5: ='Torque Assumptions · Growth & o'!B5*IF(AND((1+'Torque Assumptions · Growth & o'!B6)=0,DATEDIF(DATE(2026,10,1),DATE(2026,10,1),"M")=0),SQRT(-1),(1+'Torque Assumptions · Growth & o'!B6)^DATEDIF(DATE(2026,10,1),DATE(2026,10,1),"M")) -> 3 | C5: ='Torque Assumptions · Growth & o'!B5*IF(AND((1+'Torque Assumptions · Growth & o'!B6)=0,DATEDIF(DATE(2026,10,1),DATE(2026,11,1),"M")=0),SQRT(-1),(1+'Torque Assumptions · Growth & o'!B6)^DATEDIF(DATE(2026,10,1),DATE(2026,11,1),"M")) -> 3.75 | D5: ='Torque Assumptions · Growth & o'!B5*IF(AND((1+'Torque Assumptions · Growth & o'!B6)=0,DATEDIF(DATE(2026,10,1),DATE(2026,12,1),"M")=0),SQRT(-1),(1+'Torque Assumptions · Growth & o'!B6)^DATEDIF(DATE(2026,10,1),DATE(2026,12,1),"M")) -> 4.6875 | E5: ='Torque Assumptions · Growth & o'!B5*IF(AND((1+'Torque Assumptions · Growth & o'!B6)=0,DATEDIF(DATE(2026,10,1),DATE(2027,1,1),"M")=0),SQRT(-1),(1+'Torque Assumptions · Growth & o'!B6)^DATEDIF(DATE(2026,10,1),DATE(2027,1,1),"M")) -> 5.859375 | F5: ='Torque Assumptions · Growth & o'!B5*IF(AND((1+'Torque Assumptions · Growth & o'!B6)=0,DATEDIF(DATE(2026,10,1),DATE(2027,2,1),"M")=0),SQRT(-1),(1+'Torque Assumptions · Growth & o'!B6)^DATEDIF(DATE(2026,10,1),DATE(2027,2,1),"M")) -> 7.3242188 | G5: ='Torque Assumptions · Growth & o'!B5*IF(AND((1+'Torque Assumptions · Growth & o'!B6)=0,DATEDIF(DATE(2026,10,1),DATE(2027,3,1),"M")=0),SQRT(-1),(1+'Torque Assumptions · Growth & o'!B6)^DATEDIF(DATE(2026,10,1),DATE(2027,3,1),"M")) -> 9.1552734 | H5: ='Torque Assumptions · Growth & o'!B5*IF(AND((1+'Torque Assumptions · Growth & o'!B6)=0,DATEDIF(DATE(2026,10,1),DATE(2027,4,1),"M")=0),SQRT(-1),(1+'Torque Assumptions · Growth & o'!B6)^DATEDIF(DATE(2026,10,1),DATE(2027,4,1),"M")) -> 11.444092 | I5: ='Torque Assumptions · Growth & o'!B5*IF(AND((1+'Torque Assumptions · Growth & o'!B6)=0,DATEDIF(DATE(2026,10,1),DATE(2027,5,1),"M")=0),SQRT(-1),(1+'Torque Assumptions · Growth & o'!B6)^DATEDIF(DATE(2026,10,1),DATE(2027,5,1),"M")) -> 14.305115 | J5: ='Torque Assumptions · Growth & o'!B5*IF(AND((1+'Torque Assumptions · Growth & o'!B6)=0,DATEDIF(DATE(2026,10,1),DATE(2027,6,1),"M")=0),SQRT(-1),(1+'Torque Assumptions · Growth & o'!B6)^DATEDIF(DATE(2026,10,1),DATE(2027,6,1),"M")) -> 17.881393 | K5: ='Torque Assumptions · Growth & o'!B5*IF(AND((1+'Torque Assumptions · Growth & o'!B6)=0,DATEDIF(DATE(2026,10,1),DATE(2027,7,1),"M")=0),SQRT(-1),(1+'Torque Assumptions · Growth & o'!B6)^DATEDIF(DATE(2026,10,1),DATE(2027,7,1),"M")) -> 22.351742 | L5: ='Torque Assumptions · Growth & o'!B5*IF(AND((1+'Torque Assumptions · Growth & o'!B6)=0,DATEDIF(DATE(2026,10,1),DATE(2027,8,1),"M")=0),SQRT(-1),(1+'Torque Assumptions · Growth & o'!B6)^DATEDIF(DATE(2026,10,1),DATE(2027,8,1),"M")) -> 27.939677 | M5: ='Torque Assumptions · Growth & o'!B5*IF(AND((1+'Torque Assumptions · Growth & o'!B6)=0,DATEDIF(DATE(2026,10,1),DATE(2027,9,1),"M")=0),SQRT(-1),(1+'Torque Assumptions · Growth & o'!B6)^DATEDIF(DATE(2026,10,1),DATE(2027,9,1),"M")) -> 34.924597
A6: Paying customers | B6: =SUM('Monthly Financial Plan · Torque'!B7,'Monthly Financial Plan · Torque'!B8,'Monthly Financial Plan · Torque'!B9) -> 3 | C6: =SUM('Monthly Financial Plan · Torque'!C7,'Monthly Financial Plan · Torque'!C8,'Monthly Financial Plan · Torque'!C9) -> 6.564 | D6: =SUM('Monthly Financial Plan · Torque'!D7,'Monthly Financial Plan · Torque'!D8,'Monthly Financial Plan · Torque'!D9) -> 10.84563 | E6: =SUM('Monthly Financial Plan · Torque'!E7,'Monthly Financial Plan · Torque'!E8,'Monthly Financial Plan · Torque'!E9) -> 16.036016 | F6: =SUM('Monthly Financial Plan · Torque'!F7,'Monthly Financial Plan · Torque'!F8,'Monthly Financial Plan · Torque'!F9) -> 22.373223 | G6: =SUM('Monthly Financial Plan · Torque'!G7,'Monthly Financial Plan · Torque'!G8,'Monthly Financial Plan · Torque'!G9) -> 30.154051 | H6: =SUM('Monthly Financial Plan · Torque'!H7,'Monthly Financial Plan · Torque'!H8,'Monthly Financial Plan · Torque'!H9) -> 39.74878 | I6: =SUM('Monthly Financial Plan · Torque'!I7,'Monthly Financial Plan · Torque'!I8,'Monthly Financial Plan · Torque'!I9) -> 51.619592 | ... M6: =SUM('Monthly Financial Plan · Torque'!M7,'Monthly Financial Plan · Torque'!M8,'Monthly Financial Plan · Torque'!M9) -> 135.7862
A7: Maintainer | B7: ='Model inputs'!D77*(1-'Torque Assumptions · Tier prici'!H5)+'Monthly Financial Plan · Torque'!B5*'Torque Assumptions · Tier prici'!G5 -> 1.5 | C7: ='Monthly Financial Plan · Torque'!B7*(1-'Torque Assumptions · Tier prici'!H5)+'Monthly Financial Plan · Torque'!C5*'Torque Assumptions · Tier prici'!G5 -> 3.255 | D7: ='Monthly Financial Plan · Torque'!C7*(1-'Torque Assumptions · Tier prici'!H5)+'Monthly Financial Plan · Torque'!D5*'Torque Assumptions · Tier prici'!G5 -> 5.33835 | E7: ='Monthly Financial Plan · Torque'!D7*(1-'Torque Assumptions · Tier prici'!H5)+'Monthly Financial Plan · Torque'!E5*'Torque Assumptions · Tier prici'!G5 -> 7.8409695 | F7: ='Monthly Financial Plan · Torque'!E7*(1-'Torque Assumptions · Tier prici'!H5)+'Monthly Financial Plan · Torque'!F5*'Torque Assumptions · Tier prici'!G5 -> 10.875801 | G7: ='Monthly Financial Plan · Torque'!F7*(1-'Torque Assumptions · Tier prici'!H5)+'Monthly Financial Plan · Torque'!G5*'Torque Assumptions · Tier prici'!G5 -> 14.583374 | H7: ='Monthly Financial Plan · Torque'!G7*(1-'Torque Assumptions · Tier prici'!H5)+'Monthly Financial Plan · Torque'!H5*'Torque Assumptions · Tier prici'!G5 -> 19.13875 | I7: ='Monthly Financial Plan · Torque'!H7*(1-'Torque Assumptions · Tier prici'!H5)+'Monthly Financial Plan · Torque'!I5*'Torque Assumptions · Tier prici'!G5 -> 24.760207 | J7: ='Monthly Financial Plan · Torque'!I7*(1-'Torque Assumptions · Tier prici'!H5)+'Monthly Financial Plan · Torque'!J5*'Torque Assumptions · Tier prici'!G5 -> 31.720087 | K7: ='Monthly Financial Plan · Torque'!J7*(1-'Torque Assumptions · Tier prici'!H5)+'Monthly Financial Plan · Torque'!K5*'Torque Assumptions · Tier prici'!G5 -> 40.358351 | L7: ='Monthly Financial Plan · Torque'!K7*(1-'Torque Assumptions · Tier prici'!H5)+'Monthly Financial Plan · Torque'!L5*'Torque Assumptions · Tier prici'!G5 -> 51.099522 | M7: ='Monthly Financial Plan · Torque'!L7*(1-'Torque Assumptions · Tier prici'!H5)+'Monthly Financial Plan · Torque'!M5*'Torque Assumptions · Tier prici'!G5 -> 64.473858
A8: Starter | B8: ='Model inputs'!D78*(1-'Torque Assumptions · Tier prici'!H6)+'Monthly Financial Plan · Torque'!B5*'Torque Assumptions · Tier prici'!G6 -> 1.05 | C8: ='Monthly Financial Plan · Torque'!B8*(1-'Torque Assumptions · Tier prici'!H6)+'Monthly Financial Plan · Torque'!C5*'Torque Assumptions · Tier prici'!G6 -> 2.31 | D8: ='Monthly Financial Plan · Torque'!C8*(1-'Torque Assumptions · Tier prici'!H6)+'Monthly Financial Plan · Torque'!D5*'Torque Assumptions · Tier prici'!G6 -> 3.835125 | E8: ='Monthly Financial Plan · Torque'!D8*(1-'Torque Assumptions · Tier prici'!H6)+'Monthly Financial Plan · Torque'!E5*'Torque Assumptions · Tier prici'!G6 -> 5.69415 | F8: ='Monthly Financial Plan · Torque'!E8*(1-'Torque Assumptions · Tier prici'!H6)+'Monthly Financial Plan · Torque'!F5*'Torque Assumptions · Tier prici'!G6 -> 7.9729191 | G8: ='Monthly Financial Plan · Torque'!F8*(1-'Torque Assumptions · Tier prici'!H6)+'Monthly Financial Plan · Torque'!G5*'Torque Assumptions · Tier prici'!G6 -> 10.778619 | H8: ='Monthly Financial Plan · Torque'!G8*(1-'Torque Assumptions · Tier prici'!H6)+'Monthly Financial Plan · Torque'!H5*'Torque Assumptions · Tier prici'!G6 -> 14.24512 | I8: ='Monthly Financial Plan · Torque'!H8*(1-'Torque Assumptions · Tier prici'!H6)+'Monthly Financial Plan · Torque'!I5*'Torque Assumptions · Tier prici'!G6 -> 18.539654 | J8: ='Monthly Financial Plan · Torque'!I8*(1-'Torque Assumptions · Tier prici'!H6)+'Monthly Financial Plan · Torque'!J5*'Torque Assumptions · Tier prici'!G6 -> 23.871159 | K8: ='Monthly Financial Plan · Torque'!J8*(1-'Torque Assumptions · Tier prici'!H6)+'Monthly Financial Plan · Torque'!K5*'Torque Assumptions · Tier prici'!G6 -> 30.500711 | L8: ='Monthly Financial Plan · Torque'!K8*(1-'Torque Assumptions · Tier prici'!H6)+'Monthly Financial Plan · Torque'!L5*'Torque Assumptions · Tier prici'!G6 -> 38.754562 | M8: ='Monthly Financial Plan · Torque'!L8*(1-'Torque Assumptions · Tier prici'!H6)+'Monthly Financial Plan · Torque'!M5*'Torque Assumptions · Tier prici'!G6 -> 49.040443
A9: Team | B9: ='Model inputs'!D79*(1-'Torque Assumptions · Tier prici'!H7)+'Monthly Financial Plan · Torque'!B5*'Torque Assumptions · Tier prici'!G7 -> 0.45 | C9: ='Monthly Financial Plan · Torque'!B9*(1-'Torque Assumptions · Tier prici'!H7)+'Monthly Financial Plan · Torque'!C5*'Torque Assumptions · Tier prici'!G7 -> 0.999 | D9: ='Monthly Financial Plan · Torque'!C9*(1-'Torque Assumptions · Tier prici'!H7)+'Monthly Financial Plan · Torque'!D5*'Torque Assumptions · Tier prici'!G7 -> 1.672155 | E9: ='Monthly Financial Plan · Torque'!D9*(1-'Torque Assumptions · Tier prici'!H7)+'Monthly Financial Plan · Torque'!E5*'Torque Assumptions · Tier prici'!G7 -> 2.5008966 | F9: ='Monthly Financial Plan · Torque'!E9*(1-'Torque Assumptions · Tier prici'!H7)+'Monthly Financial Plan · Torque'!F5*'Torque Assumptions · Tier prici'!G7 -> 3.5245025 | G9: ='Monthly Financial Plan · Torque'!F9*(1-'Torque Assumptions · Tier prici'!H7)+'Monthly Financial Plan · Torque'!G5*'Torque Assumptions · Tier prici'!G7 -> 4.7920585 | H9: ='Monthly Financial Plan · Torque'!G9*(1-'Torque Assumptions · Tier prici'!H7)+'Monthly Financial Plan · Torque'!H5*'Torque Assumptions · Tier prici'!G7 -> 6.3649105 | I9: ='Monthly Financial Plan · Torque'!H9*(1-'Torque Assumptions · Tier prici'!H7)+'Monthly Financial Plan · Torque'!I5*'Torque Assumptions · Tier prici'!G7 -> 8.3197304 | J9: ='Monthly Financial Plan · Torque'!I9*(1-'Torque Assumptions · Tier prici'!H7)+'Monthly Financial Plan · Torque'!J5*'Torque Assumptions · Tier prici'!G7 -> 10.752347 | K9: ='Monthly Financial Plan · Torque'!J9*(1-'Torque Assumptions · Tier prici'!H7)+'Monthly Financial Plan · Torque'!K5*'Torque Assumptions · Tier prici'!G7 -> 13.782538 | L9: ='Monthly Financial Plan · Torque'!K9*(1-'Torque Assumptions · Tier prici'!H7)+'Monthly Financial Plan · Torque'!L5*'Torque Assumptions · Tier prici'!G7 -> 17.560014 | M9: ='Monthly Financial Plan · Torque'!L9*(1-'Torque Assumptions · Tier prici'!H7)+'Monthly Financial Plan · Torque'!M5*'Torque Assumptions · Tier prici'!G7 -> 22.271903
A10: Churned customers | B10: =SUM('Monthly Financial Plan · Torque'!B11,'Monthly Financial Plan · Torque'!B12,'Monthly Financial Plan · Torque'!B13) -> 0 | C10: =SUM('Monthly Financial Plan · Torque'!C11,'Monthly Financial Plan · Torque'!C12,'Monthly Financial Plan · Torque'!C13) -> 0.186 | D10: =SUM('Monthly Financial Plan · Torque'!D11,'Monthly Financial Plan · Torque'!D12,'Monthly Financial Plan · Torque'!D13) -> 0.40587 | E10: =SUM('Monthly Financial Plan · Torque'!E11,'Monthly Financial Plan · Torque'!E12,'Monthly Financial Plan · Torque'!E13) -> 0.6689889 | F10: =SUM('Monthly Financial Plan · Torque'!F11,'Monthly Financial Plan · Torque'!F12,'Monthly Financial Plan · Torque'!F13) -> 0.98701196 | G10: =SUM('Monthly Financial Plan · Torque'!G11,'Monthly Financial Plan · Torque'!G12,'Monthly Financial Plan · Torque'!G13) -> 1.3744451 | H10: =SUM('Monthly Financial Plan · Torque'!H11,'Monthly Financial Plan · Torque'!H12,'Monthly Financial Plan · Torque'!H13) -> 1.8493626 | I10: =SUM('Monthly Financial Plan · Torque'!I11,'Monthly Financial Plan · Torque'!I12,'Monthly Financial Plan · Torque'!I13) -> 2.4343033 | ... M10: =SUM('Monthly Financial Plan · Torque'!M11,'Monthly Financial Plan · Torque'!M12,'Monthly Financial Plan · Torque'!M13) -> 6.5524903
A11: Maintainer | B11: ='Model inputs'!D77*'Torque Assumptions · Tier prici'!H5 -> 0 | C11: ='Monthly Financial Plan · Torque'!B7*'Torque Assumptions · Tier prici'!H5 -> 0.12 | D11: ='Monthly Financial Plan · Torque'!C7*'Torque Assumptions · Tier prici'!H5 -> 0.2604 | E11: ='Monthly Financial Plan · Torque'!D7*'Torque Assumptions · Tier prici'!H5 -> 0.427068 | F11: ='Monthly Financial Plan · Torque'!E7*'Torque Assumptions · Tier prici'!H5 -> 0.62727756 | G11: ='Monthly Financial Plan · Torque'!F7*'Torque Assumptions · Tier prici'!H5 -> 0.87006411 | H11: ='Monthly Financial Plan · Torque'!G7*'Torque Assumptions · Tier prici'!H5 -> 1.1666699 | I11: ='Monthly Financial Plan · Torque'!H7*'Torque Assumptions · Tier prici'!H5 -> 1.5311 | J11: ='Monthly Financial Plan · Torque'!I7*'Torque Assumptions · Tier prici'!H5 -> 1.9808166 | K11: ='Monthly Financial Plan · Torque'!J7*'Torque Assumptions · Tier prici'!H5 -> 2.537607 | L11: ='Monthly Financial Plan · Torque'!K7*'Torque Assumptions · Tier prici'!H5 -> 3.2286681 | M11: ='Monthly Financial Plan · Torque'!L7*'Torque Assumptions · Tier prici'!H5 -> 4.0879617
A12: Starter | B12: ='Model inputs'!D78*'Torque Assumptions · Tier prici'!H6 -> 0 | C12: ='Monthly Financial Plan · Torque'!B8*'Torque Assumptions · Tier prici'!H6 -> 0.0525 | D12: ='Monthly Financial Plan · Torque'!C8*'Torque Assumptions · Tier prici'!H6 -> 0.1155 | E12: ='Monthly Financial Plan · Torque'!D8*'Torque Assumptions · Tier prici'!H6 -> 0.19175625 | F12: ='Monthly Financial Plan · Torque'!E8*'Torque Assumptions · Tier prici'!H6 -> 0.2847075 | G12: ='Monthly Financial Plan · Torque'!F8*'Torque Assumptions · Tier prici'!H6 -> 0.39864595 | H12: ='Monthly Financial Plan · Torque'!G8*'Torque Assumptions · Tier prici'!H6 -> 0.53893094 | I12: ='Monthly Financial Plan · Torque'!H8*'Torque Assumptions · Tier prici'!H6 -> 0.712256 | J12: ='Monthly Financial Plan · Torque'!I8*'Torque Assumptions · Tier prici'!H6 -> 0.92698271 | K12: ='Monthly Financial Plan · Torque'!J8*'Torque Assumptions · Tier prici'!H6 -> 1.193558 | L12: ='Monthly Financial Plan · Torque'!K8*'Torque Assumptions · Tier prici'!H6 -> 1.5250355 | M12: ='Monthly Financial Plan · Torque'!L8*'Torque Assumptions · Tier prici'!H6 -> 1.9377281
A13: Team | B13: ='Model inputs'!D79*'Torque Assumptions · Tier prici'!H7 -> 0 | C13: ='Monthly Financial Plan · Torque'!B9*'Torque Assumptions · Tier prici'!H7 -> 0.0135 | D13: ='Monthly Financial Plan · Torque'!C9*'Torque Assumptions · Tier prici'!H7 -> 0.02997 | E13: ='Monthly Financial Plan · Torque'!D9*'Torque Assumptions · Tier prici'!H7 -> 0.05016465 | F13: ='Monthly Financial Plan · Torque'!E9*'Torque Assumptions · Tier prici'!H7 -> 0.075026898 | G13: ='Monthly Financial Plan · Torque'!F9*'Torque Assumptions · Tier prici'!H7 -> 0.10573508 | H13: ='Monthly Financial Plan · Torque'!G9*'Torque Assumptions · Tier prici'!H7 -> 0.14376175 | I13: ='Monthly Financial Plan · Torque'!H9*'Torque Assumptions · Tier prici'!H7 -> 0.19094731 | J13: ='Monthly Financial Plan · Torque'!I9*'Torque Assumptions · Tier prici'!H7 -> 0.24959191 | K13: ='Monthly Financial Plan · Torque'!J9*'Torque Assumptions · Tier prici'!H7 -> 0.32257042 | L13: ='Monthly Financial Plan · Torque'!K9*'Torque Assumptions · Tier prici'!H7 -> 0.41347615 | M13: ='Monthly Financial Plan · Torque'!L9*'Torque Assumptions · Tier prici'!H7 -> 0.52680041
A14: Issue runs | B14: =SUM('Monthly Financial Plan · Torque'!B15,'Monthly Financial Plan · Torque'!B16,'Monthly Financial Plan · Torque'!B17) -> 138.075 | C14: =SUM('Monthly Financial Plan · Torque'!C15,'Monthly Financial Plan · Torque'!C16,'Monthly Financial Plan · Torque'!C17) -> 304.845 | D14: =SUM('Monthly Financial Plan · Torque'!D15,'Monthly Financial Plan · Torque'!D16,'Monthly Financial Plan · Torque'!D17) -> 507.76841 | E14: =SUM('Monthly Financial Plan · Torque'!E15,'Monthly Financial Plan · Torque'!E16,'Monthly Financial Plan · Torque'!E17) -> 756.15215 | F14: =SUM('Monthly Financial Plan · Torque'!F15,'Monthly Financial Plan · Torque'!F16,'Monthly Financial Plan · Torque'!F17) -> 1061.6148 | G14: =SUM('Monthly Financial Plan · Torque'!G15,'Monthly Financial Plan · Torque'!G16,'Monthly Financial Plan · Torque'!G17) -> 1438.6653 | H14: =SUM('Monthly Financial Plan · Torque'!H15,'Monthly Financial Plan · Torque'!H16,'Monthly Financial Plan · Torque'!H17) -> 1905.4269 | I14: =SUM('Monthly Financial Plan · Torque'!I15,'Monthly Financial Plan · Torque'!I16,'Monthly Financial Plan · Torque'!I17) -> 2484.541 | ... M14: =SUM('Monthly Financial Plan · Torque'!M15,'Monthly Financial Plan · Torque'!M16,'Monthly Financial Plan · Torque'!M17) -> 6607.2894
A15: Maintainer | B15: ='Monthly Financial Plan · Torque'!B7*'Torque Assumptions · Tier prici'!I5 -> 17.25 | C15: ='Monthly Financial Plan · Torque'!C7*'Torque Assumptions · Tier prici'!I5 -> 37.4325 | D15: ='Monthly Financial Plan · Torque'!D7*'Torque Assumptions · Tier prici'!I5 -> 61.391025 | E15: ='Monthly Financial Plan · Torque'!E7*'Torque Assumptions · Tier prici'!I5 -> 90.171149 | F15: ='Monthly Financial Plan · Torque'!F7*'Torque Assumptions · Tier prici'!I5 -> 125.07172 | G15: ='Monthly Financial Plan · Torque'!G7*'Torque Assumptions · Tier prici'!I5 -> 167.7088 | H15: ='Monthly Financial Plan · Torque'!H7*'Torque Assumptions · Tier prici'!I5 -> 220.09562 | I15: ='Monthly Financial Plan · Torque'!I7*'Torque Assumptions · Tier prici'!I5 -> 284.74238 | J15: ='Monthly Financial Plan · Torque'!J7*'Torque Assumptions · Tier prici'!I5 -> 364.78101 | K15: ='Monthly Financial Plan · Torque'!K7*'Torque Assumptions · Tier prici'!I5 -> 464.12104 | L15: ='Monthly Financial Plan · Torque'!L7*'Torque Assumptions · Tier prici'!I5 -> 587.6445 | M15: ='Monthly Financial Plan · Torque'!M7*'Torque Assumptions · Tier prici'!I5 -> 741.44937
A16: Starter | B16: ='Monthly Financial Plan · Torque'!B8*'Torque Assumptions · Tier prici'!I6 -> 40.95 | C16: ='Monthly Financial Plan · Torque'!C8*'Torque Assumptions · Tier prici'!I6 -> 90.09 | D16: ='Monthly Financial Plan · Torque'!D8*'Torque Assumptions · Tier prici'!I6 -> 149.56987 | E16: ='Monthly Financial Plan · Torque'!E8*'Torque Assumptions · Tier prici'!I6 -> 222.07185 | F16: ='Monthly Financial Plan · Torque'!F8*'Torque Assumptions · Tier prici'!I6 -> 310.94384 | G16: ='Monthly Financial Plan · Torque'!G8*'Torque Assumptions · Tier prici'!I6 -> 420.36613 | H16: ='Monthly Financial Plan · Torque'!H8*'Torque Assumptions · Tier prici'!I6 -> 555.55968 | I16: ='Monthly Financial Plan · Torque'!I8*'Torque Assumptions · Tier prici'!I6 -> 723.04651 | J16: ='Monthly Financial Plan · Torque'!J8*'Torque Assumptions · Tier prici'!I6 -> 930.97521 | K16: ='Monthly Financial Plan · Torque'!K8*'Torque Assumptions · Tier prici'!I6 -> 1189.5277 | L16: ='Monthly Financial Plan · Torque'!L8*'Torque Assumptions · Tier prici'!I6 -> 1511.4279 | M16: ='Monthly Financial Plan · Torque'!M8*'Torque Assumptions · Tier prici'!I6 -> 1912.5773
A17: Team | B17: ='Monthly Financial Plan · Torque'!B9*'Torque Assumptions · Tier prici'!I7 -> 79.875 | C17: ='Monthly Financial Plan · Torque'!C9*'Torque Assumptions · Tier prici'!I7 -> 177.3225 | D17: ='Monthly Financial Plan · Torque'!D9*'Torque Assumptions · Tier prici'!I7 -> 296.80751 | E17: ='Monthly Financial Plan · Torque'!E9*'Torque Assumptions · Tier prici'!I7 -> 443.90915 | F17: ='Monthly Financial Plan · Torque'!F9*'Torque Assumptions · Tier prici'!I7 -> 625.5992 | G17: ='Monthly Financial Plan · Torque'!G9*'Torque Assumptions · Tier prici'!I7 -> 850.59038 | H17: ='Monthly Financial Plan · Torque'!H9*'Torque Assumptions · Tier prici'!I7 -> 1129.7716 | I17: ='Monthly Financial Plan · Torque'!I9*'Torque Assumptions · Tier prici'!I7 -> 1476.7521 | J17: ='Monthly Financial Plan · Torque'!J9*'Torque Assumptions · Tier prici'!I7 -> 1908.5417 | K17: ='Monthly Financial Plan · Torque'!K9*'Torque Assumptions · Tier prici'!I7 -> 2446.4006 | L17: ='Monthly Financial Plan · Torque'!L9*'Torque Assumptions · Tier prici'!I7 -> 3116.9024 | M17: ='Monthly Financial Plan · Torque'!M9*'Torque Assumptions · Tier prici'!I7 -> 3953.2628
A18: Verified pull requests | B18: =SUM('Monthly Financial Plan · Torque'!B15,'Monthly Financial Plan · Torque'!B16,'Monthly Financial Plan · Torque'!B17)*'Torque Assumptions · Run cost a'!B17 -> 82.845 | C18: =SUM('Monthly Financial Plan · Torque'!C15,'Monthly Financial Plan · Torque'!C16,'Monthly Financial Plan · Torque'!C17)*'Torque Assumptions · Run cost a'!B17 -> 182.907 | D18: =SUM('Monthly Financial Plan · Torque'!D15,'Monthly Financial Plan · Torque'!D16,'Monthly Financial Plan · Torque'!D17)*'Torque Assumptions · Run cost a'!B17 -> 304.66105 | E18: =SUM('Monthly Financial Plan · Torque'!E15,'Monthly Financial Plan · Torque'!E16,'Monthly Financial Plan · Torque'!E17)*'Torque Assumptions · Run cost a'!B17 -> 453.69129 | F18: =SUM('Monthly Financial Plan · Torque'!F15,'Monthly Financial Plan · Torque'!F16,'Monthly Financial Plan · Torque'!F17)*'Torque Assumptions · Run cost a'!B17 -> 636.96885 | G18: =SUM('Monthly Financial Plan · Torque'!G15,'Monthly Financial Plan · Torque'!G16,'Monthly Financial Plan · Torque'!G17)*'Torque Assumptions · Run cost a'!B17 -> 863.19919 | H18: =SUM('Monthly Financial Plan · Torque'!H15,'Monthly Financial Plan · Torque'!H16,'Monthly Financial Plan · Torque'!H17)*'Torque Assumptions · Run cost a'!B17 -> 1143.2561 | I18: =SUM('Monthly Financial Plan · Torque'!I15,'Monthly Financial Plan · Torque'!I16,'Monthly Financial Plan · Torque'!I17)*'Torque Assumptions · Run cost a'!B17 -> 1490.7246 | J18: =SUM('Monthly Financial Plan · Torque'!J15,'Monthly Financial Plan · Torque'!J16,'Monthly Financial Plan · Torque'!J17)*'Torque Assumptions · Run cost a'!B17 -> 1922.5787 | K18: =SUM('Monthly Financial Plan · Torque'!K15,'Monthly Financial Plan · Torque'!K16,'Monthly Financial Plan · Torque'!K17)*'Torque Assumptions · Run cost a'!B17 -> 2460.0296 | L18: =SUM('Monthly Financial Plan · Torque'!L15,'Monthly Financial Plan · Torque'!L16,'Monthly Financial Plan · Torque'!L17)*'Torque Assumptions · Run cost a'!B17 -> 3129.5849 | M18: =SUM('Monthly Financial Plan · Torque'!M15,'Monthly Financial Plan · Torque'!M16,'Monthly Financial Plan · Torque'!M17)*'Torque Assumptions · Run cost a'!B17 -> 3964.3736
A19: Subscription revenue | B19: =SUM('Monthly Financial Plan · Torque'!B20,'Monthly Financial Plan · Torque'!B21,'Monthly Financial Plan · Torque'!B22) -> 327 | C19: =SUM('Monthly Financial Plan · Torque'!C20,'Monthly Financial Plan · Torque'!C21,'Monthly Financial Plan · Torque'!C22) -> 721.686 | D19: =SUM('Monthly Financial Plan · Torque'!D20,'Monthly Financial Plan · Torque'!D21,'Monthly Financial Plan · Torque'!D22) -> 1201.6794 | E19: =SUM('Monthly Financial Plan · Torque'!E20,'Monthly Financial Plan · Torque'!E21,'Monthly Financial Plan · Torque'!E22) -> 1788.9667 | F19: =SUM('Monthly Financial Plan · Torque'!F20,'Monthly Financial Plan · Torque'!F21,'Monthly Financial Plan · Torque'!F22) -> 2510.9937 | G19: =SUM('Monthly Financial Plan · Torque'!G20,'Monthly Financial Plan · Torque'!G21,'Monthly Financial Plan · Torque'!G22) -> 3402.0324 | H19: =SUM('Monthly Financial Plan · Torque'!H20,'Monthly Financial Plan · Torque'!H21,'Monthly Financial Plan · Torque'!H22) -> 4504.8899 | I19: =SUM('Monthly Financial Plan · Torque'!I20,'Monthly Financial Plan · Torque'!I21,'Monthly Financial Plan · Torque'!I22) -> 5873.0442 | ... M19: =SUM('Monthly Financial Plan · Torque'!M20,'Monthly Financial Plan · Torque'!M21,'Monthly Financial Plan · Torque'!M22) -> 15611.235
A20: Maintainer | B20: ='Monthly Financial Plan · Torque'!B7*'Torque Assumptions · Tier prici'!B5 -> 43.5 | C20: ='Monthly Financial Plan · Torque'!C7*'Torque Assumptions · Tier prici'!B5 -> 94.395 | D20: ='Monthly Financial Plan · Torque'!D7*'Torque Assumptions · Tier prici'!B5 -> 154.81215 | E20: ='Monthly Financial Plan · Torque'!E7*'Torque Assumptions · Tier prici'!B5 -> 227.38812 | F20: ='Monthly Financial Plan · Torque'!F7*'Torque Assumptions · Tier prici'!B5 -> 315.39824 | G20: ='Monthly Financial Plan · Torque'!G7*'Torque Assumptions · Tier prici'!B5 -> 422.91784 | H20: ='Monthly Financial Plan · Torque'!H7*'Torque Assumptions · Tier prici'!B5 -> 555.02375 | I20: ='Monthly Financial Plan · Torque'!I7*'Torque Assumptions · Tier prici'!B5 -> 718.04601 | J20: ='Monthly Financial Plan · Torque'!J7*'Torque Assumptions · Tier prici'!B5 -> 919.88254 | K20: ='Monthly Financial Plan · Torque'!K7*'Torque Assumptions · Tier prici'!B5 -> 1170.3922 | L20: ='Monthly Financial Plan · Torque'!L7*'Torque Assumptions · Tier prici'!B5 -> 1481.8861 | M20: ='Monthly Financial Plan · Torque'!M7*'Torque Assumptions · Tier prici'!B5 -> 1869.7419
A21: Starter | B21: ='Monthly Financial Plan · Torque'!B8*'Torque Assumptions · Tier prici'!B6 -> 103.95 | C21: ='Monthly Financial Plan · Torque'!C8*'Torque Assumptions · Tier prici'!B6 -> 228.69 | D21: ='Monthly Financial Plan · Torque'!D8*'Torque Assumptions · Tier prici'!B6 -> 379.67737 | E21: ='Monthly Financial Plan · Torque'!E8*'Torque Assumptions · Tier prici'!B6 -> 563.72085 | F21: ='Monthly Financial Plan · Torque'!F8*'Torque Assumptions · Tier prici'!B6 -> 789.31899 | G21: ='Monthly Financial Plan · Torque'!G8*'Torque Assumptions · Tier prici'!B6 -> 1067.0833 | H21: ='Monthly Financial Plan · Torque'!H8*'Torque Assumptions · Tier prici'!B6 -> 1410.2669 | I21: ='Monthly Financial Plan · Torque'!I8*'Torque Assumptions · Tier prici'!B6 -> 1835.4258 | J21: ='Monthly Financial Plan · Torque'!J8*'Torque Assumptions · Tier prici'!B6 -> 2363.2448 | K21: ='Monthly Financial Plan · Torque'!K8*'Torque Assumptions · Tier prici'!B6 -> 3019.5704 | L21: ='Monthly Financial Plan · Torque'!L8*'Torque Assumptions · Tier prici'!B6 -> 3836.7017 | M21: ='Monthly Financial Plan · Torque'!M8*'Torque Assumptions · Tier prici'!B6 -> 4855.0039
A22: Team | B22: ='Monthly Financial Plan · Torque'!B9*'Torque Assumptions · Tier prici'!B7 -> 179.55 | C22: ='Monthly Financial Plan · Torque'!C9*'Torque Assumptions · Tier prici'!B7 -> 398.601 | D22: ='Monthly Financial Plan · Torque'!D9*'Torque Assumptions · Tier prici'!B7 -> 667.18984 | E22: ='Monthly Financial Plan · Torque'!E9*'Torque Assumptions · Tier prici'!B7 -> 997.85774 | F22: ='Monthly Financial Plan · Torque'!F9*'Torque Assumptions · Tier prici'!B7 -> 1406.2765 | G22: ='Monthly Financial Plan · Torque'!G9*'Torque Assumptions · Tier prici'!B7 -> 1912.0313 | H22: ='Monthly Financial Plan · Torque'!H9*'Torque Assumptions · Tier prici'!B7 -> 2539.5993 | I22: ='Monthly Financial Plan · Torque'!I9*'Torque Assumptions · Tier prici'!B7 -> 3319.5724 | J22: ='Monthly Financial Plan · Torque'!J9*'Torque Assumptions · Tier prici'!B7 -> 4290.1866 | K22: ='Monthly Financial Plan · Torque'!K9*'Torque Assumptions · Tier prici'!B7 -> 5499.2328 | L22: ='Monthly Financial Plan · Torque'!L9*'Torque Assumptions · Tier prici'!B7 -> 7006.4455 | M22: ='Monthly Financial Plan · Torque'!M9*'Torque Assumptions · Tier prici'!B7 -> 8886.4892
A23: Overage revenue | B23: =SUM('Monthly Financial Plan · Torque'!B24,'Monthly Financial Plan · Torque'!B25,'Monthly Financial Plan · Torque'!B26) -> 22.4625 | C23: =SUM('Monthly Financial Plan · Torque'!C24,'Monthly Financial Plan · Torque'!C25,'Monthly Financial Plan · Torque'!C26) -> 49.63125 | D23: =SUM('Monthly Financial Plan · Torque'!D24,'Monthly Financial Plan · Torque'!D25,'Monthly Financial Plan · Torque'!D26) -> 82.724681 | E23: =SUM('Monthly Financial Plan · Torque'!E24,'Monthly Financial Plan · Torque'!E25,'Monthly Financial Plan · Torque'!E26) -> 123.26362 | F23: =SUM('Monthly Financial Plan · Torque'!F24,'Monthly Financial Plan · Torque'!F25,'Monthly Financial Plan · Torque'!F26) -> 173.14703 | G23: =SUM('Monthly Financial Plan · Torque'!G24,'Monthly Financial Plan · Torque'!G25,'Monthly Financial Plan · Torque'!G26) -> 234.74665 | H23: =SUM('Monthly Financial Plan · Torque'!H24,'Monthly Financial Plan · Torque'!H25,'Monthly Financial Plan · Torque'!H26) -> 311.02531 | I23: =SUM('Monthly Financial Plan · Torque'!I24,'Monthly Financial Plan · Torque'!I25,'Monthly Financial Plan · Torque'!I26) -> 405.68484 | ... M23: =SUM('Monthly Financial Plan · Torque'!M24,'Monthly Financial Plan · Torque'!M25,'Monthly Financial Plan · Torque'!M26) -> 1079.7724
A24: Maintainer | B24: ='Monthly Financial Plan · Torque'!B7*'Torque Assumptions · Tier prici'!F5*'Torque Assumptions · Tier prici'!D5 -> 1.875 | C24: ='Monthly Financial Plan · Torque'!C7*'Torque Assumptions · Tier prici'!F5*'Torque Assumptions · Tier prici'!D5 -> 4.06875 | D24: ='Monthly Financial Plan · Torque'!D7*'Torque Assumptions · Tier prici'!F5*'Torque Assumptions · Tier prici'!D5 -> 6.6729375 | E24: ='Monthly Financial Plan · Torque'!E7*'Torque Assumptions · Tier prici'!F5*'Torque Assumptions · Tier prici'!D5 -> 9.8012119 | F24: ='Monthly Financial Plan · Torque'!F7*'Torque Assumptions · Tier prici'!F5*'Torque Assumptions · Tier prici'!D5 -> 13.594752 | G24: ='Monthly Financial Plan · Torque'!G7*'Torque Assumptions · Tier prici'!F5*'Torque Assumptions · Tier prici'!D5 -> 18.229217 | H24: ='Monthly Financial Plan · Torque'!H7*'Torque Assumptions · Tier prici'!F5*'Torque Assumptions · Tier prici'!D5 -> 23.923437 | I24: ='Monthly Financial Plan · Torque'!I7*'Torque Assumptions · Tier prici'!F5*'Torque Assumptions · Tier prici'!D5 -> 30.950259 | J24: ='Monthly Financial Plan · Torque'!J7*'Torque Assumptions · Tier prici'!F5*'Torque Assumptions · Tier prici'!D5 -> 39.650109 | K24: ='Monthly Financial Plan · Torque'!K7*'Torque Assumptions · Tier prici'!F5*'Torque Assumptions · Tier prici'!D5 -> 50.447939 | L24: ='Monthly Financial Plan · Torque'!L7*'Torque Assumptions · Tier prici'!F5*'Torque Assumptions · Tier prici'!D5 -> 63.874402 | M24: ='Monthly Financial Plan · Torque'!M7*'Torque Assumptions · Tier prici'!F5*'Torque Assumptions · Tier prici'!D5 -> 80.592323
A25: Starter | B25: ='Monthly Financial Plan · Torque'!B8*'Torque Assumptions · Tier prici'!F6*'Torque Assumptions · Tier prici'!D6 -> 7.0875 | C25: ='Monthly Financial Plan · Torque'!C8*'Torque Assumptions · Tier prici'!F6*'Torque Assumptions · Tier prici'!D6 -> 15.5925 | D25: ='Monthly Financial Plan · Torque'!D8*'Torque Assumptions · Tier prici'!F6*'Torque Assumptions · Tier prici'!D6 -> 25.887094 | E25: ='Monthly Financial Plan · Torque'!E8*'Torque Assumptions · Tier prici'!F6*'Torque Assumptions · Tier prici'!D6 -> 38.435512 | F25: ='Monthly Financial Plan · Torque'!F8*'Torque Assumptions · Tier prici'!F6*'Torque Assumptions · Tier prici'!D6 -> 53.817204 | G25: ='Monthly Financial Plan · Torque'!G8*'Torque Assumptions · Tier prici'!F6*'Torque Assumptions · Tier prici'!D6 -> 72.755677 | H25: ='Monthly Financial Plan · Torque'!H8*'Torque Assumptions · Tier prici'!F6*'Torque Assumptions · Tier prici'!D6 -> 96.15456 | I25: ='Monthly Financial Plan · Torque'!I8*'Torque Assumptions · Tier prici'!F6*'Torque Assumptions · Tier prici'!D6 -> 125.14267 | J25: ='Monthly Financial Plan · Torque'!J8*'Torque Assumptions · Tier prici'!F6*'Torque Assumptions · Tier prici'!D6 -> 161.13032 | K25: ='Monthly Financial Plan · Torque'!K8*'Torque Assumptions · Tier prici'!F6*'Torque Assumptions · Tier prici'!D6 -> 205.8798 | L25: ='Monthly Financial Plan · Torque'!L8*'Torque Assumptions · Tier prici'!F6*'Torque Assumptions · Tier prici'!D6 -> 261.5933 | M25: ='Monthly Financial Plan · Torque'!M8*'Torque Assumptions · Tier prici'!F6*'Torque Assumptions · Tier prici'!D6 -> 331.02299
A26: Team | B26: ='Monthly Financial Plan · Torque'!B9*'Torque Assumptions · Tier prici'!F7*'Torque Assumptions · Tier prici'!D7 -> 13.5 | C26: ='Monthly Financial Plan · Torque'!C9*'Torque Assumptions · Tier prici'!F7*'Torque Assumptions · Tier prici'!D7 -> 29.97 | D26: ='Monthly Financial Plan · Torque'!D9*'Torque Assumptions · Tier prici'!F7*'Torque Assumptions · Tier prici'!D7 -> 50.16465 | E26: ='Monthly Financial Plan · Torque'!E9*'Torque Assumptions · Tier prici'!F7*'Torque Assumptions · Tier prici'!D7 -> 75.026898 | F26: ='Monthly Financial Plan · Torque'!F9*'Torque Assumptions · Tier prici'!F7*'Torque Assumptions · Tier prici'!D7 -> 105.73508 | G26: ='Monthly Financial Plan · Torque'!G9*'Torque Assumptions · Tier prici'!F7*'Torque Assumptions · Tier prici'!D7 -> 143.76175 | H26: ='Monthly Financial Plan · Torque'!H9*'Torque Assumptions · Tier prici'!F7*'Torque Assumptions · Tier prici'!D7 -> 190.94731 | I26: ='Monthly Financial Plan · Torque'!I9*'Torque Assumptions · Tier prici'!F7*'Torque Assumptions · Tier prici'!D7 -> 249.59191 | J26: ='Monthly Financial Plan · Torque'!J9*'Torque Assumptions · Tier prici'!F7*'Torque Assumptions · Tier prici'!D7 -> 322.57042 | K26: ='Monthly Financial Plan · Torque'!K9*'Torque Assumptions · Tier prici'!F7*'Torque Assumptions · Tier prici'!D7 -> 413.47615 | L26: ='Monthly Financial Plan · Torque'!L9*'Torque Assumptions · Tier prici'!F7*'Torque Assumptions · Tier prici'!D7 -> 526.80041 | M26: ='Monthly Financial Plan · Torque'!M9*'Torque Assumptions · Tier prici'!F7*'Torque Assumptions · Tier prici'!D7 -> 668.15708
A27: Total revenue | B27: =SUM('Monthly Financial Plan · Torque'!B20,'Monthly Financial Plan · Torque'!B21,'Monthly Financial Plan · Torque'!B22)+SUM('Monthly Financial Plan · Torque'!B24,'Monthly Financial Plan · Torque'!B25,'Monthly Financial Plan · Torque'!B26) -> 349.4625 | C27: =SUM('Monthly Financial Plan · Torque'!C20,'Monthly Financial Plan · Torque'!C21,'Monthly Financial Plan · Torque'!C22)+SUM('Monthly Financial Plan · Torque'!C24,'Monthly Financial Plan · Torque'!C25,'Monthly Financial Plan · Torque'!C26) -> 771.31725 | D27: =SUM('Monthly Financial Plan · Torque'!D20,'Monthly Financial Plan · Torque'!D21,'Monthly Financial Plan · Torque'!D22)+SUM('Monthly Financial Plan · Torque'!D24,'Monthly Financial Plan · Torque'!D25,'Monthly Financial Plan · Torque'!D26) -> 1284.4041 | E27: =SUM('Monthly Financial Plan · Torque'!E20,'Monthly Financial Plan · Torque'!E21,'Monthly Financial Plan · Torque'!E22)+SUM('Monthly Financial Plan · Torque'!E24,'Monthly Financial Plan · Torque'!E25,'Monthly Financial Plan · Torque'!E26) -> 1912.2303 | F27: =SUM('Monthly Financial Plan · Torque'!F20,'Monthly Financial Plan · Torque'!F21,'Monthly Financial Plan · Torque'!F22)+SUM('Monthly Financial Plan · Torque'!F24,'Monthly Financial Plan · Torque'!F25,'Monthly Financial Plan · Torque'!F26) -> 2684.1408 | G27: =SUM('Monthly Financial Plan · Torque'!G20,'Monthly Financial Plan · Torque'!G21,'Monthly Financial Plan · Torque'!G22)+SUM('Monthly Financial Plan · Torque'!G24,'Monthly Financial Plan · Torque'!G25,'Monthly Financial Plan · Torque'!G26) -> 3636.7791 | H27: =SUM('Monthly Financial Plan · Torque'!H20,'Monthly Financial Plan · Torque'!H21,'Monthly Financial Plan · Torque'!H22)+SUM('Monthly Financial Plan · Torque'!H24,'Monthly Financial Plan · Torque'!H25,'Monthly Financial Plan · Torque'!H26) -> 4815.9152 | I27: =SUM('Monthly Financial Plan · Torque'!I20,'Monthly Financial Plan · Torque'!I21,'Monthly Financial Plan · Torque'!I22)+SUM('Monthly Financial Plan · Torque'!I24,'Monthly Financial Plan · Torque'!I25,'Monthly Financial Plan · Torque'!I26) -> 6278.729 | ... M27: =SUM('Monthly Financial Plan · Torque'!M20,'Monthly Financial Plan · Torque'!M21,'Monthly Financial Plan · Torque'!M22)+SUM('Monthly Financial Plan · Torque'!M24,'Monthly Financial Plan · Torque'!M25,'Monthly Financial Plan · Torque'!M26) -> 16691.007
A28: LLM token cost | B28: =SUM('Monthly Financial Plan · Torque'!B15,'Monthly Financial Plan · Torque'!B16,'Monthly Financial Plan · Torque'!B17)*'Unit Economics & Sensitivity ·'!B8 -> 134.62312 | C28: =SUM('Monthly Financial Plan · Torque'!C15,'Monthly Financial Plan · Torque'!C16,'Monthly Financial Plan · Torque'!C17)*'Unit Economics & Sensitivity ·'!B8 -> 297.22388 | D28: =SUM('Monthly Financial Plan · Torque'!D15,'Monthly Financial Plan · Torque'!D16,'Monthly Financial Plan · Torque'!D17)*'Unit Economics & Sensitivity ·'!B8 -> 495.0742 | E28: =SUM('Monthly Financial Plan · Torque'!E15,'Monthly Financial Plan · Torque'!E16,'Monthly Financial Plan · Torque'!E17)*'Unit Economics & Sensitivity ·'!B8 -> 737.24834 | F28: =SUM('Monthly Financial Plan · Torque'!F15,'Monthly Financial Plan · Torque'!F16,'Monthly Financial Plan · Torque'!F17)*'Unit Economics & Sensitivity ·'!B8 -> 1035.0744 | G28: =SUM('Monthly Financial Plan · Torque'!G15,'Monthly Financial Plan · Torque'!G16,'Monthly Financial Plan · Torque'!G17)*'Unit Economics & Sensitivity ·'!B8 -> 1402.6987 | H28: =SUM('Monthly Financial Plan · Torque'!H15,'Monthly Financial Plan · Torque'!H16,'Monthly Financial Plan · Torque'!H17)*'Unit Economics & Sensitivity ·'!B8 -> 1857.7912 | I28: =SUM('Monthly Financial Plan · Torque'!I15,'Monthly Financial Plan · Torque'!I16,'Monthly Financial Plan · Torque'!I17)*'Unit Economics & Sensitivity ·'!B8 -> 2422.4275 | J28: =SUM('Monthly Financial Plan · Torque'!J15,'Monthly Financial Plan · Torque'!J16,'Monthly Financial Plan · Torque'!J17)*'Unit Economics & Sensitivity ·'!B8 -> 3124.1904 | K28: =SUM('Monthly Financial Plan · Torque'!K15,'Monthly Financial Plan · Torque'!K16,'Monthly Financial Plan · Torque'!K17)*'Unit Economics & Sensitivity ·'!B8 -> 3997.5481 | L28: =SUM('Monthly Financial Plan · Torque'!L15,'Monthly Financial Plan · Torque'!L16,'Monthly Financial Plan · Torque'!L17)*'Unit Economics & Sensitivity ·'!B8 -> 5085.5755 | M28: =SUM('Monthly Financial Plan · Torque'!M15,'Monthly Financial Plan · Torque'!M16,'Monthly Financial Plan · Torque'!M17)*'Unit Economics & Sensitivity ·'!B8 -> 6442.1072
A29: Sandbox compute cost | B29: =SUM('Monthly Financial Plan · Torque'!B15,'Monthly Financial Plan · Torque'!B16,'Monthly Financial Plan · Torque'!B17)*'Unit Economics & Sensitivity ·'!B9 -> 10.76985 | C29: =SUM('Monthly Financial Plan · Torque'!C15,'Monthly Financial Plan · Torque'!C16,'Monthly Financial Plan · Torque'!C17)*'Unit Economics & Sensitivity ·'!B9 -> 23.77791 | D29: =SUM('Monthly Financial Plan · Torque'!D15,'Monthly Financial Plan · Torque'!D16,'Monthly Financial Plan · Torque'!D17)*'Unit Economics & Sensitivity ·'!B9 -> 39.605936 | E29: =SUM('Monthly Financial Plan · Torque'!E15,'Monthly Financial Plan · Torque'!E16,'Monthly Financial Plan · Torque'!E17)*'Unit Economics & Sensitivity ·'!B9 -> 58.979867 | F29: =SUM('Monthly Financial Plan · Torque'!F15,'Monthly Financial Plan · Torque'!F16,'Monthly Financial Plan · Torque'!F17)*'Unit Economics & Sensitivity ·'!B9 -> 82.805951 | G29: =SUM('Monthly Financial Plan · Torque'!G15,'Monthly Financial Plan · Torque'!G16,'Monthly Financial Plan · Torque'!G17)*'Unit Economics & Sensitivity ·'!B9 -> 112.21589 | H29: =SUM('Monthly Financial Plan · Torque'!H15,'Monthly Financial Plan · Torque'!H16,'Monthly Financial Plan · Torque'!H17)*'Unit Economics & Sensitivity ·'!B9 -> 148.6233 | I29: =SUM('Monthly Financial Plan · Torque'!I15,'Monthly Financial Plan · Torque'!I16,'Monthly Financial Plan · Torque'!I17)*'Unit Economics & Sensitivity ·'!B9 -> 193.7942 | J29: =SUM('Monthly Financial Plan · Torque'!J15,'Monthly Financial Plan · Torque'!J16,'Monthly Financial Plan · Torque'!J17)*'Unit Economics & Sensitivity ·'!B9 -> 249.93524 | K29: =SUM('Monthly Financial Plan · Torque'!K15,'Monthly Financial Plan · Torque'!K16,'Monthly Financial Plan · Torque'!K17)*'Unit Economics & Sensitivity ·'!B9 -> 319.80385 | L29: =SUM('Monthly Financial Plan · Torque'!L15,'Monthly Financial Plan · Torque'!L16,'Monthly Financial Plan · Torque'!L17)*'Unit Economics & Sensitivity ·'!B9 -> 406.84604 | M29: =SUM('Monthly Financial Plan · Torque'!M15,'Monthly Financial Plan · Torque'!M16,'Monthly Financial Plan · Torque'!M17)*'Unit Economics & Sensitivity ·'!B9 -> 515.36857
A30: Observability and context cost | B30: =SUM('Monthly Financial Plan · Torque'!B15,'Monthly Financial Plan · Torque'!B16,'Monthly Financial Plan · Torque'!B17)*('Torque Assumptions · Run cost a'!B14+'Torque Assumptions · Run cost a'!B15) -> 2.7615 | C30: =SUM('Monthly Financial Plan · Torque'!C15,'Monthly Financial Plan · Torque'!C16,'Monthly Financial Plan · Torque'!C17)*('Torque Assumptions · Run cost a'!B14+'Torque Assumptions · Run cost a'!B15) -> 6.0969 | D30: =SUM('Monthly Financial Plan · Torque'!D15,'Monthly Financial Plan · Torque'!D16,'Monthly Financial Plan · Torque'!D17)*('Torque Assumptions · Run cost a'!B14+'Torque Assumptions · Run cost a'!B15) -> 10.155368 | E30: =SUM('Monthly Financial Plan · Torque'!E15,'Monthly Financial Plan · Torque'!E16,'Monthly Financial Plan · Torque'!E17)*('Torque Assumptions · Run cost a'!B14+'Torque Assumptions · Run cost a'!B15) -> 15.123043 | F30: =SUM('Monthly Financial Plan · Torque'!F15,'Monthly Financial Plan · Torque'!F16,'Monthly Financial Plan · Torque'!F17)*('Torque Assumptions · Run cost a'!B14+'Torque Assumptions · Run cost a'!B15) -> 21.232295 | G30: =SUM('Monthly Financial Plan · Torque'!G15,'Monthly Financial Plan · Torque'!G16,'Monthly Financial Plan · Torque'!G17)*('Torque Assumptions · Run cost a'!B14+'Torque Assumptions · Run cost a'!B15) -> 28.773306 | H30: =SUM('Monthly Financial Plan · Torque'!H15,'Monthly Financial Plan · Torque'!H16,'Monthly Financial Plan · Torque'!H17)*('Torque Assumptions · Run cost a'!B14+'Torque Assumptions · Run cost a'!B15) -> 38.108538 | I30: =SUM('Monthly Financial Plan · Torque'!I15,'Monthly Financial Plan · Torque'!I16,'Monthly Financial Plan · Torque'!I17)*('Torque Assumptions · Run cost a'!B14+'Torque Assumptions · Run cost a'!B15) -> 49.690821 | J30: =SUM('Monthly Financial Plan · Torque'!J15,'Monthly Financial Plan · Torque'!J16,'Monthly Financial Plan · Torque'!J17)*('Torque Assumptions · Run cost a'!B14+'Torque Assumptions · Run cost a'!B15) -> 64.085958 | K30: =SUM('Monthly Financial Plan · Torque'!K15,'Monthly Financial Plan · Torque'!K16,'Monthly Financial Plan · Torque'!K17)*('Torque Assumptions · Run cost a'!B14+'Torque Assumptions · Run cost a'!B15) -> 82.000986 | L30: =SUM('Monthly Financial Plan · Torque'!L15,'Monthly Financial Plan · Torque'!L16,'Monthly Financial Plan · Torque'!L17)*('Torque Assumptions · Run cost a'!B14+'Torque Assumptions · Run cost a'!B15) -> 104.3195 | M30: =SUM('Monthly Financial Plan · Torque'!M15,'Monthly Financial Plan · Torque'!M16,'Monthly Financial Plan · Torque'!M17)*('Torque Assumptions · Run cost a'!B14+'Torque Assumptions · Run cost a'!B15) -> 132.14579
A31: Storage cost | B31: =SUM('Monthly Financial Plan · Torque'!B15,'Monthly Financial Plan · Torque'!B16,'Monthly Financial Plan · Torque'!B17)*'Torque Assumptions · Run cost a'!B16 -> 0.690375 | C31: =SUM('Monthly Financial Plan · Torque'!C15,'Monthly Financial Plan · Torque'!C16,'Monthly Financial Plan · Torque'!C17)*'Torque Assumptions · Run cost a'!B16 -> 1.524225 | D31: =SUM('Monthly Financial Plan · Torque'!D15,'Monthly Financial Plan · Torque'!D16,'Monthly Financial Plan · Torque'!D17)*'Torque Assumptions · Run cost a'!B16 -> 2.5388421 | E31: =SUM('Monthly Financial Plan · Torque'!E15,'Monthly Financial Plan · Torque'!E16,'Monthly Financial Plan · Torque'!E17)*'Torque Assumptions · Run cost a'!B16 -> 3.7807607 | F31: =SUM('Monthly Financial Plan · Torque'!F15,'Monthly Financial Plan · Torque'!F16,'Monthly Financial Plan · Torque'!F17)*'Torque Assumptions · Run cost a'!B16 -> 5.3080738 | G31: =SUM('Monthly Financial Plan · Torque'!G15,'Monthly Financial Plan · Torque'!G16,'Monthly Financial Plan · Torque'!G17)*'Torque Assumptions · Run cost a'!B16 -> 7.1933265 | H31: =SUM('Monthly Financial Plan · Torque'!H15,'Monthly Financial Plan · Torque'!H16,'Monthly Financial Plan · Torque'!H17)*'Torque Assumptions · Run cost a'!B16 -> 9.5271346 | I31: =SUM('Monthly Financial Plan · Torque'!I15,'Monthly Financial Plan · Torque'!I16,'Monthly Financial Plan · Torque'!I17)*'Torque Assumptions · Run cost a'!B16 -> 12.422705 | J31: =SUM('Monthly Financial Plan · Torque'!J15,'Monthly Financial Plan · Torque'!J16,'Monthly Financial Plan · Torque'!J17)*'Torque Assumptions · Run cost a'!B16 -> 16.021489 | K31: =SUM('Monthly Financial Plan · Torque'!K15,'Monthly Financial Plan · Torque'!K16,'Monthly Financial Plan · Torque'!K17)*'Torque Assumptions · Run cost a'!B16 -> 20.500247 | L31: =SUM('Monthly Financial Plan · Torque'!L15,'Monthly Financial Plan · Torque'!L16,'Monthly Financial Plan · Torque'!L17)*'Torque Assumptions · Run cost a'!B16 -> 26.079874 | M31: =SUM('Monthly Financial Plan · Torque'!M15,'Monthly Financial Plan · Torque'!M16,'Monthly Financial Plan · Torque'!M17)*'Torque Assumptions · Run cost a'!B16 -> 33.036447
A32: Hosting cost | B32: =IF('Torque Assumptions · Growth & o'!B7="","",'Torque Assumptions · Growth & o'!B7) -> 150 | C32: =IF('Torque Assumptions · Growth & o'!B7="","",'Torque Assumptions · Growth & o'!B7) -> 150 | D32: =IF('Torque Assumptions · Growth & o'!B7="","",'Torque Assumptions · Growth & o'!B7) -> 150 | E32: =IF('Torque Assumptions · Growth & o'!B7="","",'Torque Assumptions · Growth & o'!B7) -> 150 | F32: =IF('Torque Assumptions · Growth & o'!B7="","",'Torque Assumptions · Growth & o'!B7) -> 150 | G32: =IF('Torque Assumptions · Growth & o'!B7="","",'Torque Assumptions · Growth & o'!B7) -> 150 | H32: =IF('Torque Assumptions · Growth & o'!B7="","",'Torque Assumptions · Growth & o'!B7) -> 150 | I32: =IF('Torque Assumptions · Growth & o'!B7="","",'Torque Assumptions · Growth & o'!B7) -> 150 | J32: =IF('Torque Assumptions · Growth & o'!B7="","",'Torque Assumptions · Growth & o'!B7) -> 150 | K32: =IF('Torque Assumptions · Growth & o'!B7="","",'Torque Assumptions · Growth & o'!B7) -> 150 | L32: =IF('Torque Assumptions · Growth & o'!B7="","",'Torque Assumptions · Growth & o'!B7) -> 150 | M32: =IF('Torque Assumptions · Growth & o'!B7="","",'Torque Assumptions · Growth & o'!B7) -> 150
A33: Payment processing cost | B33: ='Monthly Financial Plan · Torque'!B27*'Torque Assumptions · Growth & o'!B13+SUM('Monthly Financial Plan · Torque'!B7,'Monthly Financial Plan · Torque'!B8,'Monthly Financial Plan · Torque'!B9)*'Torque Assumptions · Growth & o'!B14 -> 11.034413 | C33: ='Monthly Financial Plan · Torque'!C27*'Torque Assumptions · Growth & o'!B13+SUM('Monthly Financial Plan · Torque'!C7,'Monthly Financial Plan · Torque'!C8,'Monthly Financial Plan · Torque'!C9)*'Torque Assumptions · Growth & o'!B14 -> 24.3374 | D33: ='Monthly Financial Plan · Torque'!D27*'Torque Assumptions · Growth & o'!B13+SUM('Monthly Financial Plan · Torque'!D7,'Monthly Financial Plan · Torque'!D8,'Monthly Financial Plan · Torque'!D9)*'Torque Assumptions · Growth & o'!B14 -> 40.501406 | E33: ='Monthly Financial Plan · Torque'!E27*'Torque Assumptions · Growth & o'!B13+SUM('Monthly Financial Plan · Torque'!E7,'Monthly Financial Plan · Torque'!E8,'Monthly Financial Plan · Torque'!E9)*'Torque Assumptions · Growth & o'!B14 -> 60.265484 | F33: ='Monthly Financial Plan · Torque'!F27*'Torque Assumptions · Growth & o'!B13+SUM('Monthly Financial Plan · Torque'!F7,'Monthly Financial Plan · Torque'!F8,'Monthly Financial Plan · Torque'!F9)*'Torque Assumptions · Growth & o'!B14 -> 84.552049 | G33: ='Monthly Financial Plan · Torque'!G27*'Torque Assumptions · Growth & o'!B13+SUM('Monthly Financial Plan · Torque'!G7,'Monthly Financial Plan · Torque'!G8,'Monthly Financial Plan · Torque'!G9)*'Torque Assumptions · Growth & o'!B14 -> 114.51281 | H33: ='Monthly Financial Plan · Torque'!H27*'Torque Assumptions · Growth & o'!B13+SUM('Monthly Financial Plan · Torque'!H7,'Monthly Financial Plan · Torque'!H8,'Monthly Financial Plan · Torque'!H9)*'Torque Assumptions · Growth & o'!B14 -> 151.58618 | I33: ='Monthly Financial Plan · Torque'!I27*'Torque Assumptions · Growth & o'!B13+SUM('Monthly Financial Plan · Torque'!I7,'Monthly Financial Plan · Torque'!I8,'Monthly Financial Plan · Torque'!I9)*'Torque Assumptions · Growth & o'!B14 -> 197.56902 | J33: ='Monthly Financial Plan · Torque'!J27*'Torque Assumptions · Growth & o'!B13+SUM('Monthly Financial Plan · Torque'!J7,'Monthly Financial Plan · Torque'!J8,'Monthly Financial Plan · Torque'!J9)*'Torque Assumptions · Growth & o'!B14 -> 254.70636 | K33: ='Monthly Financial Plan · Torque'!K27*'Torque Assumptions · Growth & o'!B13+SUM('Monthly Financial Plan · Torque'!K7,'Monthly Financial Plan · Torque'!K8,'Monthly Financial Plan · Torque'!K9)*'Torque Assumptions · Growth & o'!B14 -> 325.80346 | L33: ='Monthly Financial Plan · Torque'!L27*'Torque Assumptions · Growth & o'!B13+SUM('Monthly Financial Plan · Torque'!L7,'Monthly Financial Plan · Torque'!L8,'Monthly Financial Plan · Torque'!L9)*'Torque Assumptions · Growth & o'!B14 -> 414.36597 | M33: ='Monthly Financial Plan · Torque'!M27*'Torque Assumptions · Growth & o'!B13+SUM('Monthly Financial Plan · Torque'!M7,'Monthly Financial Plan · Torque'!M8,'Monthly Financial Plan · Torque'!M9)*'Torque Assumptions · Growth & o'!B14 -> 524.77508
A34: Cost of revenue | B34: ='Monthly Financial Plan · Torque'!B28+'Monthly Financial Plan · Torque'!B29+'Monthly Financial Plan · Torque'!B30+'Monthly Financial Plan · Torque'!B31+'Monthly Financial Plan · Torque'!B32+'Monthly Financial Plan · Torque'!B33 -> 309.87926 | C34: ='Monthly Financial Plan · Torque'!C28+'Monthly Financial Plan · Torque'!C29+'Monthly Financial Plan · Torque'!C30+'Monthly Financial Plan · Torque'!C31+'Monthly Financial Plan · Torque'!C32+'Monthly Financial Plan · Torque'!C33 -> 502.96031 | D34: ='Monthly Financial Plan · Torque'!D28+'Monthly Financial Plan · Torque'!D29+'Monthly Financial Plan · Torque'!D30+'Monthly Financial Plan · Torque'!D31+'Monthly Financial Plan · Torque'!D32+'Monthly Financial Plan · Torque'!D33 -> 737.87576 | E34: ='Monthly Financial Plan · Torque'!E28+'Monthly Financial Plan · Torque'!E29+'Monthly Financial Plan · Torque'!E30+'Monthly Financial Plan · Torque'!E31+'Monthly Financial Plan · Torque'!E32+'Monthly Financial Plan · Torque'!E33 -> 1025.3975 | F34: ='Monthly Financial Plan · Torque'!F28+'Monthly Financial Plan · Torque'!F29+'Monthly Financial Plan · Torque'!F30+'Monthly Financial Plan · Torque'!F31+'Monthly Financial Plan · Torque'!F32+'Monthly Financial Plan · Torque'!F33 -> 1378.9728 | G34: ='Monthly Financial Plan · Torque'!G28+'Monthly Financial Plan · Torque'!G29+'Monthly Financial Plan · Torque'!G30+'Monthly Financial Plan · Torque'!G31+'Monthly Financial Plan · Torque'!G32+'Monthly Financial Plan · Torque'!G33 -> 1815.394 | H34: ='Monthly Financial Plan · Torque'!H28+'Monthly Financial Plan · Torque'!H29+'Monthly Financial Plan · Torque'!H30+'Monthly Financial Plan · Torque'!H31+'Monthly Financial Plan · Torque'!H32+'Monthly Financial Plan · Torque'!H33 -> 2355.6364 | I34: ='Monthly Financial Plan · Torque'!I28+'Monthly Financial Plan · Torque'!I29+'Monthly Financial Plan · Torque'!I30+'Monthly Financial Plan · Torque'!I31+'Monthly Financial Plan · Torque'!I32+'Monthly Financial Plan · Torque'!I33 -> 3025.9043 | ... M34: ='Monthly Financial Plan · Torque'!M28+'Monthly Financial Plan · Torque'!M29+'Monthly Financial Plan · Torque'!M30+'Monthly Financial Plan · Torque'!M31+'Monthly Financial Plan · Torque'!M32+'Monthly Financial Plan · Torque'!M33 -> 7797.433
A35: Gross profit before credits | B35: ='Monthly Financial Plan · Torque'!B27-'Monthly Financial Plan · Torque'!B34 -> 39.583237 | C35: ='Monthly Financial Plan · Torque'!C27-'Monthly Financial Plan · Torque'!C34 -> 268.35694 | D35: ='Monthly Financial Plan · Torque'!D27-'Monthly Financial Plan · Torque'!D34 -> 546.5283 | E35: ='Monthly Financial Plan · Torque'!E27-'Monthly Financial Plan · Torque'!E34 -> 886.83283 | F35: ='Monthly Financial Plan · Torque'!F27-'Monthly Financial Plan · Torque'!F34 -> 1305.168 | G35: ='Monthly Financial Plan · Torque'!G27-'Monthly Financial Plan · Torque'!G34 -> 1821.3851 | H35: ='Monthly Financial Plan · Torque'!H27-'Monthly Financial Plan · Torque'!H34 -> 2460.2788 | I35: ='Monthly Financial Plan · Torque'!I27-'Monthly Financial Plan · Torque'!I34 -> 3252.8248 | ... M35: ='Monthly Financial Plan · Torque'!M27-'Monthly Financial Plan · Torque'!M34 -> 8893.5743
A36: Gross margin before credits | B36: =IFERROR('Monthly Financial Plan · Torque'!B35/'Monthly Financial Plan · Torque'!B27,"") -> 0.11326891 | C36: =IFERROR('Monthly Financial Plan · Torque'!C35/'Monthly Financial Plan · Torque'!C27,"") -> 0.34792031 | D36: =IFERROR('Monthly Financial Plan · Torque'!D35/'Monthly Financial Plan · Torque'!D27,"") -> 0.42551119 | E36: =IFERROR('Monthly Financial Plan · Torque'!E35/'Monthly Financial Plan · Torque'!E27,"") -> 0.46376884 | F36: =IFERROR('Monthly Financial Plan · Torque'!F35/'Monthly Financial Plan · Torque'!F27,"") -> 0.4862517 | G36: =IFERROR('Monthly Financial Plan · Torque'!G35/'Monthly Financial Plan · Torque'!G27,"") -> 0.50082368 | H36: =IFERROR('Monthly Financial Plan · Torque'!H35/'Monthly Financial Plan · Torque'!H27,"") -> 0.51086423 | I36: =IFERROR('Monthly Financial Plan · Torque'!I35/'Monthly Financial Plan · Torque'!I27,"") -> 0.51807058 | ... M36: =IFERROR('Monthly Financial Plan · Torque'!M35/'Monthly Financial Plan · Torque'!M27,"") -> 0.53283628
A37: Hackathon credits available | B37: =45 -> 45 | C37: =0 -> 0 | D37: =0 -> 0 | E37: 0 | F37: 0 | G37: 0 | H37: 0 | I37: 0 | J37: 0 | K37: 0 | L37: 0 | M37: 0
A38: Hackathon credits applied | B38: =MIN('Monthly Financial Plan · Torque'!B37,'Monthly Financial Plan · Torque'!B28+'Monthly Financial Plan · Torque'!B29) -> 45 | C38: =MIN('Monthly Financial Plan · Torque'!C37,'Monthly Financial Plan · Torque'!C28+'Monthly Financial Plan · Torque'!C29) -> 0 | D38: =MIN('Monthly Financial Plan · Torque'!D37,'Monthly Financial Plan · Torque'!D28+'Monthly Financial Plan · Torque'!D29) -> 0 | E38: =MIN('Monthly Financial Plan · Torque'!E37,'Monthly Financial Plan · Torque'!E28+'Monthly Financial Plan · Torque'!E29) -> 0 | F38: =MIN('Monthly Financial Plan · Torque'!F37,'Monthly Financial Plan · Torque'!F28+'Monthly Financial Plan · Torque'!F29) -> 0 | G38: =MIN('Monthly Financial Plan · Torque'!G37,'Monthly Financial Plan · Torque'!G28+'Monthly Financial Plan · Torque'!G29) -> 0 | H38: =MIN('Monthly Financial Plan · Torque'!H37,'Monthly Financial Plan · Torque'!H28+'Monthly Financial Plan · Torque'!H29) -> 0 | I38: =MIN('Monthly Financial Plan · Torque'!I37,'Monthly Financial Plan · Torque'!I28+'Monthly Financial Plan · Torque'!I29) -> 0 | ... M38: =MIN('Monthly Financial Plan · Torque'!M37,'Monthly Financial Plan · Torque'!M28+'Monthly Financial Plan · Torque'!M29) -> 0
A39: Gross profit after credits | B39: ='Monthly Financial Plan · Torque'!B35+'Monthly Financial Plan · Torque'!B38 -> 84.583237 | C39: ='Monthly Financial Plan · Torque'!C35+'Monthly Financial Plan · Torque'!C38 -> 268.35694 | D39: ='Monthly Financial Plan · Torque'!D35+'Monthly Financial Plan · Torque'!D38 -> 546.5283 | E39: ='Monthly Financial Plan · Torque'!E35+'Monthly Financial Plan · Torque'!E38 -> 886.83283 | F39: ='Monthly Financial Plan · Torque'!F35+'Monthly Financial Plan · Torque'!F38 -> 1305.168 | G39: ='Monthly Financial Plan · Torque'!G35+'Monthly Financial Plan · Torque'!G38 -> 1821.3851 | H39: ='Monthly Financial Plan · Torque'!H35+'Monthly Financial Plan · Torque'!H38 -> 2460.2788 | I39: ='Monthly Financial Plan · Torque'!I35+'Monthly Financial Plan · Torque'!I38 -> 3252.8248 | ... M39: ='Monthly Financial Plan · Torque'!M35+'Monthly Financial Plan · Torque'!M38 -> 8893.5743
A40: Gross margin after credits | B40: =IFERROR('Monthly Financial Plan · Torque'!B39/'Monthly Financial Plan · Torque'!B27,"") -> 0.24203809 | C40: =IFERROR('Monthly Financial Plan · Torque'!C39/'Monthly Financial Plan · Torque'!C27,"") -> 0.34792031 | D40: =IFERROR('Monthly Financial Plan · Torque'!D39/'Monthly Financial Plan · Torque'!D27,"") -> 0.42551119 | E40: =IFERROR('Monthly Financial Plan · Torque'!E39/'Monthly Financial Plan · Torque'!E27,"") -> 0.46376884 | F40: =IFERROR('Monthly Financial Plan · Torque'!F39/'Monthly Financial Plan · Torque'!F27,"") -> 0.4862517 | G40: =IFERROR('Monthly Financial Plan · Torque'!G39/'Monthly Financial Plan · Torque'!G27,"") -> 0.50082368 | H40: =IFERROR('Monthly Financial Plan · Torque'!H39/'Monthly Financial Plan · Torque'!H27,"") -> 0.51086423 | I40: =IFERROR('Monthly Financial Plan · Torque'!I39/'Monthly Financial Plan · Torque'!I27,"") -> 0.51807058 | ... M40: =IFERROR('Monthly Financial Plan · Torque'!M39/'Monthly Financial Plan · Torque'!M27,"") -> 0.53283628
